Workbook
Name SegmentaçãodeDados_dia: #N/A
Name Usuario: #REF!

Sheet TD Painel
M2: Ano | N2: 2026 | R2: DiretoriaComercial | S2: DIRETORIA SPI
C3: ano | D3: 2026 | M3: canal_loja | N3: HOUSE | R3: Ano | S3: 2026
C4: nom_empreendimento | D4: All | M4: loja_ags | N4: NÃO
C5: diretoria | D5: DIRETORIA SPI | R5: DataBaseAssinaturaContratoSalesforce | S5: NomeGerente | T5: NomeCorretor | U5: NomeLoja | V5: NomeImobiliaria | W5: # Vendas
C6: dia | D6: All | M6: DataBase | N6: regional_co | O6: nom_gerente | P6: TotalCorretores | Q6: TotalCorretoresMais10DiasSemLogin | R6: jan/2026 | T6: RAFAEL FERNANDES DECHICHI | U6: AGENTE DE SONHOS – EXTERIOR (NP 1) | W6: 3
M7: 01/01/2026 | N7: SENSIA CP | O7: IDELSO JOSE DA SILVA SANTOS DE ASSIS | P7: 19 | Q7: 15 | R7: jan/2026 | T7: WELLINGHTON CESAR PEREIRA FIGUEIREDO | U7: SENSIA IMOB CAMPINAS | V7: M.L.N DE CASTRO CARVALHO | W7: 1
C8: data_base | D8: canal_loja | E8: gerente | F8: supervisor_imob | G8: nom_corretor | H8: nom_imobiliaria | I8: status_funil | J8: regional | K8: Funil_Real | M8: 01/01/2026 | N8: SENSIA RP | O8: DOUGLAS MENDES DE AGUIAR RODRIGUES | P8: 12 | Q8: 8 | R8: jan/2026 | T8: WELLINGHTON CESAR PEREIRA FIGUEIREDO | U8: SENSIA IMOB CAMPINAS | V8: RE IMOBILIARIA EIRELI EPP | W8: 5
C9: 01/06/2026 | D9: AGS | G9: ANA RAQUEL CANDIDO MARCHETI | I9: LEAD | J9: SP INT 3 | K9: 24 | M9: 01/01/2026 | N9: SP INT 1 | O9: ANDERSON COSTA CARAPETA | P9: 13 | Q9: 6 | R9: jan/2026 | T9: WELLINGHTON CESAR PEREIRA FIGUEIREDO | U9: SENSIA IMOB CAMPINAS | V9: SATUS NEGOCIOS IMOBILIARIOS LTDA | W9: 2
C10: 01/06/2026 | D10: AGS | G10: ANNA CAROLINA REIS DECHICHI | I10: DOCUMENTAÇÃO ENVIADA | J10: SP INT 4 | K10: 18 | M10: 01/01/2026 | N10: SP INT 1 | O10: EVANDRO DE BRITO | P10: 16 | Q10: 7 | R10: jan/2026 | T10: WELLINGHTON CESAR PEREIRA FIGUEIREDO | U10: SENSIA IMOB CAMPINAS | V10: TASSELLI ADM E SERVIÇÕS IMOBILIARIOS LTDA CAMPINAS IMOB | W10: 1
C11: 01/06/2026 | D11: AGS | G11: ANNA CAROLINA REIS DECHICHI | I11: DOCUMENTAÇÃO EM ANÁLISE | J11: SP INT 4 | K11: 18 | M11: 01/01/2026 | N11: SP INT 1 | O11: FABIO HENRIQUE VIDOTTI FERREIRA | P11: 2 | R11: jan/2026 | S11: ADALTON JOSE DA SILVA | T11: AUDILAINE SANTANA DE SOUZA | U11: LOJA EQUIPE VIRTUAL BOTUCATU 1 | W11: 1
C12: 01/06/2026 | D12: AGS | G12: ANNA CAROLINA REIS DECHICHI | I12: CPF ANALISADO | J12: SP INT 4 | K12: 18 | M12: 01/01/2026 | N12: SP INT 1 | O12: PABLO MEDEIROS DA SILVA GADELHA | P12: 17 | Q12: 13 | R12: jan/2026 | S12: ADALTON JOSE DA SILVA | T12: CLEIDE APARECIDA RIBEIRA DA SILVA | U12: LOJA EQUIPE VIRTUAL BOTUCATU 1 | W12: 1
C13: 01/06/2026 | D13: AGS | G13: ANNA CAROLINA REIS DECHICHI | I13: CPF APROVADO | J13: SP INT 4 | K13: 16 | M13: 01/01/2026 | N13: SP INT 1 | O13: THAINA PIOLOGO MARQUES DE QUEIROZ | P13: 1 | R13: jan/2026 | S13: ADALTON JOSE DA SILVA | T13: CLEITON FRANCISCO XAVIER | U13: LOJA EQUIPE VIRTUAL BOTUCATU 1 | W13: 2
C14: 01/06/2026 | D14: AGS | G14: ANNA CAROLINA REIS DECHICHI | I14: CPF CONDICIONADO | J14: SP INT 4 | K14: 2 | M14: 01/01/2026 | N14: SP INT 1 | O14: THAMIRES PEREIRA COSTA | P14: 18 | Q14: 5 | R14: jan/2026 | S14: ADALTON JOSE DA SILVA | T14: ISABELA CAROLINE LEMES | U14: LOJA EQUIPE VIRTUAL BOTUCATU 1 | W14: 1
C15: 01/06/2026 | D15: AGS | G15: ANNA CAROLINA REIS DECHICHI | I15: CONTRATO GERADO | J15: SP INT 4 | K15: 23 | M15: 01/01/2026 | N15: SP INT 1 | O15: TIAGO AUGUSTO DA COSTA | P15: 17 | Q15: 5 | R15: jan/2026 | S15: ADALTON JOSE DA SILVA | T15: JEAN CARLOS DE OLIVEIRA GOMES | U15: LOJA EQUIPE VIRTUAL BOTUCATU 1 | W15: 1
C16: 01/06/2026 | D16: AGS | G16: ANNA CAROLINA REIS DECHICHI | I16: CONTRATO ASSINADO | J16: SP INT 4 | K16: 11 | M16: 01/01/2026 | N16: SP INT 2 | O16: DOMINIQUE DAMASO DE SALES | P16: 14 | Q16: 9 | R16: jan/2026 | S16: ADALTON JOSE DA SILVA | T16: JOAO PAULO CAVAZZANA | U16: LOJA EQUIPE VIRTUAL BOTUCATU 1 | W16: 1
C17: 01/06/2026 | D17: AGS | G17: ANNA CAROLINA REIS DECHICHI | I17: GANHO | J17: SP INT 4 | K17: 12 | M17: 01/01/2026 | N17: SP INT 2 | O17: FLAVIANO DE SOUZA CORREA | P17: 15 | Q17: 6 | R17: jan/2026 | S17: ADALTON JOSE DA SILVA | T17: MARCOS ANTÔNIO GARCIA | U17: LOJA EQUIPE VIRTUAL BOTUCATU 1 | W17: 2
C18: 01/06/2026 | D18: AGS | G18: BRUNO PEREIRA SANTOS | I18: LEAD | J18: SP INT 4 | K18: 121 | M18: 01/01/2026 | N18: SP INT 2 | O18: HEITOR NEVES MANCUZO | P18: 19 | Q18: 10 | R18: jan/2026 | S18: ADALTON JOSE DA SILVA | T18: ROSANGELA APARECIDA PINTO SIMÃO | U18: LOJA EQUIPE VIRTUAL BOTUCATU 1 | W18: 1
C19: 01/06/2026 | D19: AGS | G19: BRUNO PEREIRA SANTOS | I19: DOCUMENTAÇÃO ENVIADA | J19: SP INT 4 | K19: 3 | M19: 01/01/2026 | N19: SP INT 2 | O19: RAFAEL MOLL RECUPERO | P19: 12 | Q19: 8 | R19: jan/2026 | S19: ADALTON JOSE DA SILVA | T19: SOLENE MATOS DE AQUINO | U19: LOJA EQUIPE VIRTUAL BOTUCATU 1 | W19: 1
C20: 01/06/2026 | D20: AGS | G20: BRUNO PEREIRA SANTOS | I20: DOCUMENTAÇÃO EM ANÁLISE | J20: SP INT 4 | K20: 3 | M20: 01/01/2026 | N20: SP INT 2 | O20: STEPHANE MASCARENHAS TEIXEIRA | P20: 13 | Q20: 12 | R20: jan/2026 | S20: ALEXANDRE FORMIGA NETO | T20: LEONARDO VICTOR DA SILVA | U20: EQUIPE CREDENCIADA JUNDIAI 2 | W20: 1
C21: 01/06/2026 | D21: AGS | G21: BRUNO PEREIRA SANTOS | I21: CPF ANALISADO | J21: SP INT 4 | K21: 3 | M21: 01/01/2026 | N21: SP INT 3 | O21: ARMANDO DONIZETTI CUSTODIO | P21: 16 | Q21: 12 | R21: jan/2026 | S21: ALEXANDRE FORMIGA NETO | T21: LUCIANA AMARAL ARAÚJO QUINTAL | U21: EQUIPE CREDENCIADA JUNDIAI 2 | W21: 2
C22: 01/06/2026 | D22: AGS | G22: BRUNO PEREIRA SANTOS | I22: CPF APROVADO | J22: SP INT 4 | K22: 3 | M22: 01/01/2026 | N22: SP INT 3 | O22: BRUNA PAULINO BENEDETTI | P22: 8 | Q22: 7 | R22: jan/2026 | S22: ALEXANDRE FORMIGA NETO | T22: PAULO ALEXANDRE JORGE | U22: EQUIPE CREDENCIADA JUNDIAI 2 | W22: 2
C23: 01/06/2026 | D23: AGS | G23: BRUNO PEREIRA SANTOS | I23: CONTRATO GERADO | J23: SP INT 4 | K23: 6 | M23: 01/01/2026 | N23: SP INT 3 | O23: DEIVES RODRIGO DA COSTA | P23: 17 | Q23: 10 | R23: jan/2026 | S23: ALEXANDRE FORMIGA NETO | T23: RUTH NUNES DOS SANTOS LIMA | U23: EQUIPE CREDENCIADA JUNDIAI 2 | W23: 1
C24: 01/06/2026 | D24: AGS | G24: BRUNO PEREIRA SANTOS | I24: CONTRATO ASSINADO | J24: SP INT 4 | K24: 3 | M24: 01/01/2026 | N24: SP INT 3 | O24: MAISA MUNIZ DA SILVA | P24: 7 | Q24: 2 | R24: jan/2026 | S24: ALINE CRISTINA MORENO | T24: ALANA EMILY DE SOUZA BATISTA | U24: IMOB CAMPINAS 2 | V24: KC CONCEITO IMOBILIARIO LTDA | W24: 1
C25: 01/06/2026 | D25: AGS | G25: BRUNO PEREIRA SANTOS | I25: GANHO | J25: SP INT 4 | K25: 2 | M25: 01/01/2026 | N25: SP INT 3 | O25: PEDRO MORENO MARQUES | P25: 13 | Q25: 7 | R25: jan/2026 | S25: ALINE CRISTINA MORENO | T25: GUSTAVO GUINATTI VENTURINI | U25: IMOB CAMPINAS 1 | V25: CARVALHO E CARVALHO CORRETAGEM DE IMÓVEIS | W25: 1
C26: 01/06/2026 | D26: AGS | G26: ELISABETE DE MORAES BOTELHO | I26: DOCUMENTAÇÃO ENVIADA | J26: SP INT 3 | K26: 1 | M26: 01/01/2026 | N26: SP INT 3 | O26: RAFAEL DOS SANTOS NOGUEIRA | P26: 1 | Q26: 1 | R26: jan/2026 | S26: ALINE CRISTINA MORENO | T26: GUSTAVO GUINATTI VENTURINI | U26: IMOB CAMPINAS 1 | V26: HUBIMOB | W26: 2
C27: 01/06/2026 | D27: AGS | G27: ELISABETE DE MORAES BOTELHO | I27: DOCUMENTAÇÃO EM ANÁLISE | J27: SP INT 3 | K27: 1 | M27: 01/01/2026 | N27: SP INT 3 | O27: THAYNA LAIS DA SILVA | P27: 13 | Q27: 9 | R27: jan/2026 | S27: ALINE CRISTINA MORENO | T27: GUSTAVO GUINATTI VENTURINI | U27: IMOB CAMPINAS 1 | V27: IMBATIVEIS IMOVEIS | W27: 1
C28: 01/06/2026 | D28: AGS | G28: ELISABETE DE MORAES BOTELHO | I28: CPF ANALISADO | J28: SP INT 3 | K28: 1 | M28: 01/01/2026 | N28: SP INT 4 | O28: ADALTON JOSE DA SILVA | P28: 12 | Q28: 3 | R28: jan/2026 | S28: ALINE CRISTINA MORENO | T28: GUSTAVO GUINATTI VENTURINI | U28: IMOB CAMPINAS 1 | V28: MICHEL CASTRO LOPES AGENTE IMOBILIARIO ME | W28: 1
C29: 01/06/2026 | D29: AGS | G29: ELISABETE DE MORAES BOTELHO | I29: CPF APROVADO | J29: SP INT 3 | K29: 1 | M29: 01/01/2026 | N29: SP INT 4 | O29: DAIANE CRISTINA JIRICO | P29: 21 | Q29: 14 | R29: jan/2026 | S29: ALINE CRISTINA MORENO | T29: GUSTAVO GUINATTI VENTURINI | U29: IMOB CAMPINAS 1 | V29: NISHIDA NEGOCIOS IMOBILIARIOS | W29: 3
C30: 01/06/2026 | D30: AGS | G30: ELTON APARECIDO DA SILVA NOGUEIRA | I30: LEAD | J30: SP INT 3 | K30: 1 | M30: 01/01/2026 | N30: SP INT 4 | O30: GUSTAVO MACHADO TENORIO | P30: 14 | Q30: 8 | R30: jan/2026 | S30: ALINE CRISTINA MORENO | T30: GUSTAVO GUINATTI VENTURINI | U30: IMOB CAMPINAS 1 | V30: RE IMOBILIARIA EIRELI EPP | W30: 1
C31: 01/06/2026 | D31: AGS | G31: ELTON APARECIDO DA SILVA NOGUEIRA | I31: DOCUMENTAÇÃO ENVIADA | J31: SP INT 3 | K31: 1 | M31: 01/01/2026 | N31: SP INT 4 | O31: JAYRANE CAROLINE MARTINS FERRARI | P31: 20 | Q31: 9 | R31: jan/2026 | S31: ALINE CRISTINA MORENO | T31: GUSTAVO GUINATTI VENTURINI | U31: IMOB CAMPINAS 1 | V31: TK ASSESSORIA IMOBILIARIA | W31: 1
C32: 01/06/2026 | D32: AGS | G32: ELTON APARECIDO DA SILVA NOGUEIRA | I32: DOCUMENTAÇÃO COM PENDÊNCIA | J32: SP INT 3 | K32: 1 | M32: 01/01/2026 | N32: SP INT 4 | O32: JULIANO MARQUES VALENTE | P32: 2 | Q32: 1 | R32: jan/2026 | S32: ALINE CRISTINA MORENO | T32: LARISSA NEVES TEIXEIRA | U32: IMOB CAMPINAS 3 | V32: BLACK NEGOCIOS IMOBILIARIOS LTDA | W32: 1
C33: 01/06/2026 | D33: AGS | G33: FLAVIA DA COSTA LUIZ | I33: LEAD | J33: SP INT 4 | K33: 197 | M33: 01/01/2026 | N33: SP INT 4 | O33: REBECA PEREIRA BONFIM DA SILVA | P33: 3 | Q33: 3 | R33: jan/2026 | S33: ALINE CRISTINA MORENO | T33: LARISSA NEVES TEIXEIRA | U33: IMOB CAMPINAS 3 | V33: CASA BROKER NEGOCIOS IMOBILIARIOS LTDA | W33: 1
C34: 01/06/2026 | D34: AGS | G34: FLAVIA DA COSTA LUIZ | I34: DOCUMENTAÇÃO ENVIADA | J34: SP INT 4 | K34: 6 | M34: 01/01/2026 | N34: SP INT 4 | O34: TIAGO ALVES CARVALHO COELHO | P34: 17 | Q34: 7 | R34: jan/2026 | S34: ALINE CRISTINA MORENO | T34: LARISSA NEVES TEIXEIRA | U34: IMOB CAMPINAS 3 | V34: HUBIMOB | W34: 4
C35: 01/06/2026 | D35: AGS | G35: FLAVIA DA COSTA LUIZ | I35: DOCUMENTAÇÃO EM ANÁLISE | J35: SP INT 4 | K35: 5 | M35: 01/01/2026 | N35: SP INT 5 | O35: JEFERSON EDUARDO NUNES | P35: 17 | Q35: 14 | R35: jan/2026 | S35: ALINE CRISTINA MORENO | T35: LARISSA NEVES TEIXEIRA | U35: IMOB CAMPINAS 3 | V35: MICHEL CASTRO LOPES AGENTE IMOBILIARIO ME | W35: 1
... C46: 01/06/2026 | D46: AGS | G46: JOAO MOYSES JUNIOR | I46: CPF CONDICIONADO | J46: SP INT 3 | K46: 1 | M46: 01/02/2026 | N46: SENSIA RP | O46: DOUGLAS MENDES DE AGUIAR RODRIGUES | P46: 17 | Q46: 10 | R46: jan/2026 | S46: ANA RAQUEL CANDIDO MARCHETI | T46: CAMILA MENDES FRANCISCO | U46: LOJA IMOB PIRACICABA | V46: BELLA IMOVEIS BRASIL | W46: 1
C47: 01/06/2026 | D47: AGS | G47: JOSE SOARES DA COSTA | I47: CONTRATO ASSINADO | J47: SP INT 3 | K47: 1 | M47: 01/02/2026 | N47: SP INT 1 | P47: 8 | Q47: 3 | R47: jan/2026 | S47: ANA RAQUEL CANDIDO MARCHETI | T47: CAMILA MENDES FRANCISCO | U47: LOJA IMOB PIRACICABA | V47: CONECTA GESTAO IMOBILIARIA | W47: 1
C48: 01/06/2026 | D48: AGS | G48: JOSE SOARES DA COSTA | I48: GANHO | J48: SP INT 3 | K48: 1 | M48: 01/02/2026 | N48: SP INT 1 | O48: ALEXANDRE MIRANDA DOS PASSOS | P48: 2 | Q48: 2 | R48: jan/2026 | S48: ANA RAQUEL CANDIDO MARCHETI | T48: CAMILA MENDES FRANCISCO | U48: LOJA IMOB PIRACICABA | V48: H12 CONSULTORIA IMOBILIARIA LTDA | W48: 1
C49: 01/06/2026 | D49: AGS | G49: JOSÉ SOARES DA COSTA | I49: LEAD | J49: SP INT 3 | K49: 1 | M49: 01/02/2026 | N49: SP INT 1 | O49: ANDERSON COSTA CARAPETA | P49: 18 | Q49: 9 | R49: jan/2026 | S49: ANA RAQUEL CANDIDO MARCHETI | T49: CAMILA MENDES FRANCISCO | U49: LOJA IMOB PIRACICABA | V49: IMOBILIARIA SANTOS | W49: 1
C50: 01/06/2026 | D50: AGS | G50: JOSÉ SOARES DA COSTA | I50: DOCUMENTAÇÃO ENVIADA | J50: SP INT 3 | K50: 5 | M50: 01/02/2026 | N50: SP INT 1 | O50: EVANDRO DE BRITO | P50: 18 | Q50: 9 | R50: jan/2026 | S50: ANA RAQUEL CANDIDO MARCHETI | T50: CAMILA MENDES FRANCISCO | U50: LOJA IMOB PIRACICABA | V50: INLOCUS IMOVEIS | W50: 2
C51: 01/06/2026 | D51: AGS | G51: JOSÉ SOARES DA COSTA | I51: DOCUMENTAÇÃO EM ANÁLISE | J51: SP INT 3 | K51: 2 | M51: 01/02/2026 | N51: SP INT 1 | O51: FABIO HENRIQUE VIDOTTI FERREIRA | P51: 4 | Q51: 2 | R51: jan/2026 | S51: ANA RAQUEL CANDIDO MARCHETI | T51: CAMILA MENDES FRANCISCO | U51: LOJA IMOB PIRACICABA | V51: INNOVA HOUSE | W51: 1
...

Sheet Planilha2
U1: regionalcompleta | V1: (Vários itens)
A2: diretoria | B2: DIRETORIA SPI | E2: diretoria | F2: DIRETORIA SPI | U2: diretoria | V2: DIRETORIA SPI
A3: canal_loja | B3: HOUSE | E3: canal_loja | F3: IMOB | U3: canal_loja | V3: IMOB
A4: data_base | B4: 01/04/2026 | E4: data_base | F4: 01/04/2026 | U4: data_base | V4: 01/03/2026
A5: dia | B5: (Vários itens) | E5: dia | F5: (Vários itens) | U5: dia | V5: All
A7: Regional | B7: Equipe House | C7: CPF Anl. | G7: CPF Anl. | U7: nom_loja | V7: supervisor_imob | W7: regional | X7: status_funil | Y7: Funil_Real
G17: CPF Anl.
E18: SP INT 1 | F18: LARISSA NEVES TEIXEIRA | G18: 7
E19: SP INT 2 | F19: HENRIQUE NEVES GARBELLINI | G19: 9 | M19: CPF Anl. | R19: Qtd_CPF_Analisado
E20: SP INT 3 | F20: LUCIANO FERREIRA DA SILVA | G20: 3 | K20: SP INT 1 | L20: ANDERSON COSTA CARAPETA | M20: 4 | P20: SP INT 1 | Q20: LARISSA NEVES TEIXEIRA | R20: 6
E21: SP INT 4 | F21: GABRIEL MACIEL RETAMEIRO | G21: 3 | K21: SP INT 2 | L21: FLAVIANO DE SOUZA CORREA | M21: 3 | P21: SP INT 2 | Q21: HENRIQUE NEVES GARBELLINI | R21: 19
E22: SP INT 5 | F22: RODRIGO MONTEIRO DE LIMA | G22: 1 | K22: SP INT 3 | P22: SP INT 3 | Q22: CAMILA MENDES FRANCISCO | R22: 6
E23: SP INT 6 | F23: CAMILA LEMOS GUIMARAES | G23: 3 | K23: SP INT 4 | L23: TIAGO ALVES CARVALHO COELHO | M23: 6 | P23: SP INT 4 | Q23: GABRIEL MACIEL RETAMEIRO | R23: 8
K24: SP INT 5 | L24: JEFERSON EDUARDO NUNES | M24: 4 | P24: SP INT 5 | Q24: VANESSA FERREIRA DE MORAES | R24: 4
K25: SP INT 6 | L25: JACKSON DE ALMEIDA PIRES | M25: 4 | P25: SP INT 6 | Q25: CAMILA LEMOS GUIMARAES | R25: 8

Sheet Planilha1
B1: Todos | C1: SPI | E1: Definitivos | F1: SPI | H1: Supervisor | I1: SPI
B2: {=_xlfn.UNIQUE('TD Painel'!#REF!)} -> #REF! | C2: =_xlfn.XLOOKUP(Planilha1!B2,'TD Painel'!#REF!,'TD Painel'!#REF!) -> #REF! | E2: HENRIQUE NEVES GARBELLINI | F2: SP INT 2 | H2: {=_xlfn._xlws.FILTER(_xlfn.ANCHORARRAY(B2), COUNTIF(E2:E30,_xlfn.ANCHORARRAY(B2)) = 0)} -> #REF! | I2: =_xlfn.XLOOKUP(H2,B:B,C:C) -> #REF!
C3: =_xlfn.XLOOKUP(Planilha1!B3,'TD Painel'!#REF!,'TD Painel'!#REF!) -> #REF! | E3: CAMILA REGINA MELCHIADES | F3: SP INT 2 | I3: =_xlfn.XLOOKUP(H3,B:B,C:C) -> #REF!
C4: =_xlfn.XLOOKUP(Planilha1!B4,'TD Painel'!#REF!,'TD Painel'!#REF!) -> #REF! | E4: VINICIUS VIEIRA FRANCISCO | F4: SP INT 4 | I4: =_xlfn.XLOOKUP(H4,B:B,C:C) -> #REF!
C5: =_xlfn.XLOOKUP(Planilha1!B5,'TD Painel'!#REF!,'TD Painel'!#REF!) -> #REF! | E5: LUCAS PEREIRA MIGUEL | F5: SP INT 2 | I5: =_xlfn.XLOOKUP(H5,B:B,C:C) -> #REF!
C6: =_xlfn.XLOOKUP(Planilha1!B6,'TD Painel'!#REF!,'TD Painel'!#REF!) -> #REF! | E6: CAMILA MENDES FRANCISCO | F6: SP INT 3 | I6: =_xlfn.XLOOKUP(H6,B:B,C:C) -> #REF!
C7: =_xlfn.XLOOKUP(Planilha1!B7,'TD Painel'!#REF!,'TD Painel'!#REF!) -> #REF! | E7: CAMILA LEMOS GUIMARAES | F7: SP INT 6 | I7: =_xlfn.XLOOKUP(H7,B:B,C:C) -> #REF!
C8: =_xlfn.XLOOKUP(Planilha1!B8,'TD Painel'!#REF!,'TD Painel'!#REF!) -> #REF! | E8: JANINE SILVA GODOY | F8: SP INT 6 | I8: =_xlfn.XLOOKUP(H8,B:B,C:C) -> #REF!
C9: =_xlfn.XLOOKUP(Planilha1!B9,'TD Painel'!#REF!,'TD Painel'!#REF!) -> #REF! | E9: JHULYANNE ALLYNE ADAO MAZIERE | F9: SP INT 6 | I9: =_xlfn.XLOOKUP(H9,B:B,C:C) -> #REF!
C10: =_xlfn.XLOOKUP(Planilha1!B10,'TD Painel'!#REF!,'TD Painel'!#REF!) -> #REF! | E10: ANA LETICIA COTRIM ALONSO | F10: SP INT 3 | I10: =_xlfn.XLOOKUP(H10,B:B,C:C) -> #REF!
C11: =_xlfn.XLOOKUP(Planilha1!B11,'TD Painel'!#REF!,'TD Painel'!#REF!) -> #REF! | E11: WANDERSON FERNANDO ALVES JUNIOR | F11: SP INT 3 | I11: =_xlfn.XLOOKUP(H11,B:B,C:C) -> #REF!
C12: =_xlfn.XLOOKUP(Planilha1!B12,'TD Painel'!#REF!,'TD Painel'!#REF!) -> #REF! | E12: GUSTAVO GUINATTI VENTURINI | F12: SP INT 1 | I12: =_xlfn.XLOOKUP(H12,B:B,C:C) -> #REF!
C13: =_xlfn.XLOOKUP(Planilha1!B13,'TD Painel'!#REF!,'TD Painel'!#REF!) -> #REF! | E13: ALINE RODRIGUES DA SILVA | F13: SP INT 5 | I13: =_xlfn.XLOOKUP(H13,B:B,C:C) -> #REF!
C14: =_xlfn.XLOOKUP(Planilha1!B14,'TD Painel'!#REF!,'TD Painel'!#REF!) -> #REF! | E14: RODRIGO PERES BORBA | F14: SP INT 1 | I14: =_xlfn.XLOOKUP(H14,B:B,C:C) -> #REF!
... C30: =_xlfn.XLOOKUP(Planilha1!B30,'TD Painel'!#REF!,'TD Painel'!#REF!) -> #REF! | E30: ARTHUR TEIXEIRA PEREIRA | F30: SP INT 4 | I30: =_xlfn.XLOOKUP(H30,B:B,C:C) -> #REF!
C31: =_xlfn.XLOOKUP(Planilha1!B31,'TD Painel'!#REF!,'TD Painel'!#REF!) -> #REF! | I31: =_xlfn.XLOOKUP(H31,B:B,C:C) -> #REF!
C32: =_xlfn.XLOOKUP(Planilha1!B32,'TD Painel'!#REF!,'TD Painel'!#REF!) -> #REF! | I32: =_xlfn.XLOOKUP(H32,B:B,C:C) -> #REF!
C33: =_xlfn.XLOOKUP(Planilha1!B33,'TD Painel'!#REF!,'TD Painel'!#REF!) -> #REF! | I33: =_xlfn.XLOOKUP(H33,B:B,C:C) -> #REF!
C34: =_xlfn.XLOOKUP(Planilha1!B34,'TD Painel'!#REF!,'TD Painel'!#REF!) -> #REF! | I34: =_xlfn.XLOOKUP(H34,B:B,C:C) -> #REF!
C35: =_xlfn.XLOOKUP(Planilha1!B35,'TD Painel'!#REF!,'TD Painel'!#REF!) -> #REF! | I35: =_xlfn.XLOOKUP(H35,B:B,C:C) -> #REF!
C36: =_xlfn.XLOOKUP(Planilha1!B36,'TD Painel'!#REF!,'TD Painel'!#REF!) -> #REF! | I36: =_xlfn.XLOOKUP(H36,B:B,C:C) -> #REF!
C37: =_xlfn.XLOOKUP(Planilha1!B37,'TD Painel'!#REF!,'TD Painel'!#REF!) -> #REF! | I37: =_xlfn.XLOOKUP(H37,B:B,C:C) -> #REF!
C38: =_xlfn.XLOOKUP(Planilha1!B38,'TD Painel'!#REF!,'TD Painel'!#REF!) -> #REF! | I38: =_xlfn.XLOOKUP(H38,B:B,C:C) -> #REF!
C39: =_xlfn.XLOOKUP(Planilha1!B39,'TD Painel'!#REF!,'TD Painel'!#REF!) -> #REF! | I39: =_xlfn.XLOOKUP(H39,B:B,C:C) -> #REF!
C40: =_xlfn.XLOOKUP(Planilha1!B40,'TD Painel'!#REF!,'TD Painel'!#REF!) -> #REF! | I40: =_xlfn.XLOOKUP(H40,B:B,C:C) -> #REF!
C41: =_xlfn.XLOOKUP(Planilha1!B41,'TD Painel'!#REF!,'TD Painel'!#REF!) -> #REF! | I41: =_xlfn.XLOOKUP(H41,B:B,C:C) -> #REF!
C42: =_xlfn.XLOOKUP(Planilha1!B42,'TD Painel'!#REF!,'TD Painel'!#REF!) -> #REF! | I42: =_xlfn.XLOOKUP(H42,B:B,C:C) -> #REF!
... C86: =_xlfn.XLOOKUP(Planilha1!B86,'TD Painel'!#REF!,'TD Painel'!#REF!) -> #REF! | I86: =_xlfn.XLOOKUP(H86,B:B,C:C) -> #REF!
C87: =_xlfn.XLOOKUP(Planilha1!B87,'TD Painel'!#REF!,'TD Painel'!#REF!) -> #REF!
C88: =_xlfn.XLOOKUP(Planilha1!B88,'TD Painel'!#REF!,'TD Painel'!#REF!) -> #REF!
C89: =_xlfn.XLOOKUP(Planilha1!B89,'TD Painel'!#REF!,'TD Painel'!#REF!) -> #REF!
C90: =_xlfn.XLOOKUP(Planilha1!B90,'TD Painel'!#REF!,'TD Painel'!#REF!) -> #REF!
C91: =_xlfn.XLOOKUP(Planilha1!B91,'TD Painel'!#REF!,'TD Painel'!#REF!) -> #REF!
C92: =_xlfn.XLOOKUP(Planilha1!B92,'TD Painel'!#REF!,'TD Painel'!#REF!) -> #REF!
C93: =_xlfn.XLOOKUP(Planilha1!B93,'TD Painel'!#REF!,'TD Painel'!#REF!) -> #REF!
C94: =_xlfn.XLOOKUP(Planilha1!B94,'TD Painel'!#REF!,'TD Painel'!#REF!) -> #REF!
C95: =_xlfn.XLOOKUP(Planilha1!B95,'TD Painel'!#REF!,'TD Painel'!#REF!) -> #REF!
C96: =_xlfn.XLOOKUP(Planilha1!B96,'TD Painel'!#REF!,'TD Painel'!#REF!) -> #REF!
C97: =_xlfn.XLOOKUP(Planilha1!B97,'TD Painel'!#REF!,'TD Painel'!#REF!) -> #REF!
C98: =_xlfn.XLOOKUP(Planilha1!B98,'TD Painel'!#REF!,'TD Painel'!#REF!) -> #REF!
...
